Workbook
Name AccessLevelList: 'Lists (Config)'!$N$4:$N$7
Name AssessmentStatusList: 'Lists (Config)'!$I$4:$I$9
Name ConfidenceList: 'Lists (Config)'!$M$4:$M$6
Name CriticalityList: 'Lists (Config)'!$C$4:$C$9
Name DiscoverySourceList: 'Lists (Config)'!$G$4:$G$11
Name DispositionList: 'Lists (Config)'!$E$4:$E$10
Name EnvironmentList: 'Lists (Config)'!$A$4:$A$10
Name HADRList: 'Lists (Config)'!$D$4:$D$9
Name ServerIDs: '2. Servers'!$A$2:$A$200
Name SupportStatusList: 'Lists (Config)'!$B$4:$B$9
Name TechnicalReviewList: 'Lists (Config)'!$O$4:$O$8
Name UsageStatusList: 'Lists (Config)'!$L$4:$L$8

Sheet Lists (Config)
A1: Value lists (edit here to update the dropdowns across all tabs)
A3: Environment | B3: Support Status | C3: Criticality | D3: HA / DR | E3: Preliminary Disposition | F3: Readiness | G3: Discovery Source | H3: In Scope (MSSQL) | I3: Assessment Status | J3: Yes/No | K3: Migration-Ready Statuses | L3: Usage Status | M3: Assessment Confidence | N3: Access Level | O3: Technical Review Status
A4: Production | B4: Supported | C4: Critical | D4: Always On AG | E4: Migrate | F4: Ready | G4: SQL Server Inspection | H4: Yes | I4: Not Started | J4: Yes | K4: Lift and Shift | L4: Active | M4: High | N4: Read Only | O4: Not Started
A5: Staging/UAT | B5: Extended Support | C5: High | D5: Failover Cluster | E5: Modernize | F5: Ready with Remediation | G5: Technical Owner Interview | H5: No | I5: Pending Analysis | J5: No | K5: Rehost | L5: Low Usage | M5: Medium | N5: Available - Scope Not Confirmed | O5: In Progress
A6: QA | B6: End of Support (EOS) | C6: Medium | D6: Mirroring | E6: Retain | F6: Needs Investigation | G6: Technical Documentation | H6: To confirm | I6: In Progress | J6: In progress | K6: Replatform | L6: Transitioning | M6: Low | N6: No Access | O6: Completed
A7: Development | B7: Unknown | C7: Low | D7: Log Shipping | E7: Consolidate | F7: Not Recommended | G7: Linked Server Analysis | I7: Pending Validation | L7: Not in Use | N7: Unknown | O7: Blocked
A8: DR | B8: Pending validation | C8: Unknown | D8: None Detected | E8: Decommission | F8: Pending validation | G8: Infrastructure Team / Documentation | I8: Completed | L8: Unknown
A9: Pending validation | C9: Pending validation | D9: Unknown | E9: Upgrade / Remediate | G9: Vendor Confirmation | I9: Blocked
A10: NA | D10: Pending validation | E10: TBD | G10: Inference
G11: Unknown

Sheet 2. Servers
A1: ServerID | B1: Server (Hostname) | C1: IP | D1: Location | E1: Network | F1: Engine / Product | G1: Edition | H1: In Scope (MSSQL) | I1: Environment | J1: Support Status | K1: Criticality | L1: HA / DR | M1: Technical Owner | N1: Business Owner | O1: Validation Method | P1: Access Level | Q1: Technical Review Status | R1: # Databases (auto) | S1: # DBs with Preliminary Disposition (auto) | T1: Notes | U1: Notes (2) | V1: Access / Evidence Limitation | W1: Required Follow-up
A2: SRV-001 | B2: BACBFBSITE | C2: 172.26.6.10 172.26.6.11 172.26.6.12 | D2: Orlando | E2: DMZ | F2: MySQL Server 8.0 | G2: - | H2: =IF(AND(ISNUMBER(SEARCH("Microsoft SQL Server",F2)),ISERROR(SEARCH("LocalDB",F2)),ISERROR(SEARCH("do not have any SQL/database installed",T2)),ISERROR(SEARCH("no business databases found",T2))),"Yes","No") -> No | I2: DR | O2: Infrastructure Team / Documentation | P2: No Access | Q2: Not Started | R2: =COUNTIF('3. Databases'!$B$2:$B$56,$A2) -> 0 | S2: =COUNTIFS('3. Databases'!$B$2:$B$56,$A2,'3. Databases'!$V$2:$V$56,"<>TBD",'3. Databases'!$V$2:$V$56,"<>") -> 0 | T2: Non-MSSQL product detected | U2: NA | V2: No SQL Server assessment required unless the scope changes. | W2: No follow-up required for the SQL Server migration assessment.
A3: SRV-002 | B3: BACBPTRANSDB1 | C3: 172.29.5.25 172.29.5.39 | D3: NAP | E3: DMZ | F3: Microsoft SQL Server 2016 (64-bit) | G3: Standard | H3: =IF(AND(ISNUMBER(SEARCH("Microsoft SQL Server",F3)),ISERROR(SEARCH("LocalDB",F3)),ISERROR(SEARCH("do not have any SQL/database installed",T3)),ISERROR(SEARCH("no business databases found",T3))),"Yes","No") -> Yes | I3: Production | J3: End of Support (EOS) | K3: High | L3: DR | M3: IT Operations Team, Renan Silva | N3: Devs | O3: Infrastructure Team / Documentation | P3: No Access | Q3: In Progress | R3: =COUNTIF('3. Databases'!$B$2:$B$56,$A3) -> 0 | S3: =COUNTIFS('3. Databases'!$B$2:$B$56,$A3,'3. Databases'!$V$2:$V$56,"<>TBD",'3. Databases'!$V$2:$V$56,"<>") -> 0 | T3: It's hosted in the DMZ. It contains databases used for development. | U3: 2026-07-30: validate with Rodney: - Validate if exists any additional instance different than the default (2026-07-31: validated with Rodney, It has no additional instances) 2026-07-30: contact Renan Silva | V3: Instance configuration, databases, jobs, feature usage, performance, backup, and HA/DR could not be validated directly. | W3: Request controlled read-only access or a validated technical extract from Infrastructure or the vendor.
A4: SRV-003 | B4: BACBPTRANSDB1 | C4: 172.29.5.25 172.29.5.39 | D4: NAP | E4: DMZ | F4: MongoDB 8.2.6 2008R2Plus SSL (64 bit) | G4: - | H4: =IF(AND(ISNUMBER(SEARCH("Microsoft SQL Server",F4)),ISERROR(SEARCH("LocalDB",F4)),ISERROR(SEARCH("do not have any SQL/database installed",T4)),ISERROR(SEARCH("no business databases found",T4))),"Yes","No") -> No | I4: Production | J4: Unknown | K4: High | L4: DR | M4: IT Operations Team | O4: Infrastructure Team / Documentation | P4: No Access | Q4: Not Started | R4: =COUNTIF('3. Databases'!$B$2:$B$56,$A4) -> 0 | S4: =COUNTIFS('3. Databases'!$B$2:$B$56,$A4,'3. Databases'!$V$2:$V$56,"<>TBD",'3. Databases'!$V$2:$V$56,"<>") -> 0 | T4: Non-MSSQL product detected | U4: NA | V4: No SQL Server assessment required unless the scope changes. | W4: No follow-up required for the SQL Server migration assessment.
A5: SRV-004 | B5: BACBPTRANSDB1 | C5: 172.29.5.25 172.29.5.39 | D5: NAP | E5: DMZ | F5: MySQL Server 8.0 | G5: - | H5: =IF(AND(ISNUMBER(SEARCH("Microsoft SQL Server",F5)),ISERROR(SEARCH("LocalDB",F5)),ISERROR(SEARCH("do not have any SQL/database installed",T5)),ISERROR(SEARCH("no business databases found",T5))),"Yes","No") -> No | I5: Production | J5: Unknown | K5: High | L5: DR | M5: IT Operations Team | O5: Infrastructure Team / Documentation | P5: No Access | Q5: Not Started | R5: =COUNTIF('3. Databases'!$B$2:$B$56,$A5) -> 0 | S5: =COUNTIFS('3. Databases'!$B$2:$B$56,$A5,'3. Databases'!$V$2:$V$56,"<>TBD",'3. Databases'!$V$2:$V$56,"<>") -> 0 | T5: Non-MSSQL product detected | U5: NA | V5: No SQL Server assessment required unless the scope changes. | W5: No follow-up required for the SQL Server migration assessment.
A6: SRV-005 | B6: BACNAPIT\SQLEXPRESS | C6: 10.198.5.190 | D6: NAP | E6: Server | F6: Microsoft SQL Server 2012 (64-bit) | G6: Express | H6: =IF(AND(ISNUMBER(SEARCH("Microsoft SQL Server",F6)),ISERROR(SEARCH("LocalDB",F6)),ISERROR(SEARCH("do not have any SQL/database installed",T6)),ISERROR(SEARCH("no business databases found",T6))),"Yes","No") -> Yes | I6: Production | K6: High | L6: DR | M6: IT Operations Team | N6: IT Operations Team | O6: Infrastructure Team / Documentation | P6: No Access | Q6: Not Started | R6: =COUNTIF('3. Databases'!$B$2:$B$56,$A6) -> 0 | S6: =COUNTIFS('3. Databases'!$B$2:$B$56,$A6,'3. Databases'!$V$2:$V$56,"<>TBD",'3. Databases'!$V$2:$V$56,"<>") -> 0 | T6: 2026-07-29: Validated with Rodney Laurent: - SSMS not installed | U6: 2026-07-30: validate with Rodney: - Using SSMS from outside the server - Validate if exists any additional instance different than the default 2026-07-31: contact Caddiel Campos regarding more information for BACNAPIT\VEEAMSQL2012 (database VeeamBackup) | V6: Instance configuration, databases, jobs, feature usage, performance, backup, and HA/DR could not be validated directly. | W6: Request controlled read-only access or a validated technical extract from Infrastructure or the vendor.
A7: SRV-007 | B7: BACSANSRV | C7: 10.198.5.131 10.198.5.132 | D7: NAP | E7: Server | F7: Microsoft SQL Server Compact 4.0 SP1 x64 ENU | G7: Express | H7: =IF(AND(ISNUMBER(SEARCH("Microsoft SQL Server",F7)),ISERROR(SEARCH("LocalDB",F7)),ISERROR(SEARCH("do not have any SQL/database installed",T7)),ISERROR(SEARCH("no business databases found",T7))),"Yes","No") -> No | I7: Production | L7: DR | M7: IT Operations Team | O7: Infrastructure Team / Documentation | P7: No Access | Q7: Not Started | R7: =COUNTIF('3. Databases'!$B$2:$B$56,$A7) -> 0 | S7: =COUNTIFS('3. Databases'!$B$2:$B$56,$A7,'3. Databases'!$V$2:$V$56,"<>TBD",'3. Databases'!$V$2:$V$56,"<>") -> 0 | T7: 2026-07-29: Validated with Rodney Laurent: No business databases found. Flag it as Out of Scope | U7: SQL Compact | V7: Instance configuration, databases, jobs, feature usage, performance, backup, and HA/DR could not be validated directly. | W7: Request controlled read-only access or a validated technical extract from Infrastructure or the vendor.
A8: SRV-006 | B8: BACSANSRV | C8: 10.198.5.131 10.198.5.132 | D8: NAP | E8: Server | F8: Microsoft SQL Server 2017 (64-bit) | G8: Express | H8: =IF(AND(ISNUMBER(SEARCH("Microsoft SQL Server",F8)),ISERROR(SEARCH("LocalDB",F8)),ISERROR(SEARCH("do not have any SQL/database installed",T8)),ISERROR(SEARCH("no business databases found",T8))),"Yes","No") -> Yes | I8: Production | K8: High | L8: DR | M8: IT Operations Team | N8: IT Operations Team | O8: Infrastructure Team / Documentation | P8: Available - Scope Not Confirmed | Q8: Not Started | R8: =COUNTIF('3. Databases'!$B$2:$B$56,$A8) -> 0 | S8: =COUNTIFS('3. Databases'!$B$2:$B$56,$A8,'3. Databases'!$V$2:$V$56,"<>TBD",'3. Databases'!$V$2:$V$56,"<>") -> 0 | T8: 2026-07-29: Data warehouse databases. | U8: 2026-07-30: validate with Rodney: - Who is the Technical Owner so I can contact them? 2026-07-30: A query was sent to Eric to determine whether it is a data warehouse (DW) and whether it falls outside the scope (2026-07-31: Eric has not knowledge about those databases) 2026-07-31: Rodney indicates to contact Fabiano | V8: Access is available, but the technical review is incomplete; instance-level features and performance evidence remain pending. | W8: Complete the instance inventory and validate features, jobs, performance, HA/DR, backups, security, and connectivity.
A9: SRV-008 | B9: BBFBDATAPARSER | C9: 10.198.5.214 | D9: NAP | E9: Server | F9: Microsoft SQL Server 2016 (64-bit) | G9: Standard | H9: =IF(AND(ISNUMBER(SEARCH("Microsoft SQL Server",F9)),ISERROR(SEARCH("LocalDB",F9)),ISERROR(SEARCH("do not have any SQL/database installed",T9)),ISERROR(SEARCH("no business databases found",T9))),"Yes","No") -> No | I9: Production | K9: High | L9: DR | M9: IT Operations Team | O9: Infrastructure Team / Documentation | P9: Available - Scope Not Confirmed | Q9: Not Started | R9: =COUNTIF('3. Databases'!$B$2:$B$56,$A9) -> 0 | S9: =COUNTIFS('3. Databases'!$B$2:$B$56,$A9,'3. Databases'!$V$2:$V$56,"<>TBD",'3. Databases'!$V$2:$V$56,"<>") -> 0 | T9: 2026-07-29: Validated with Rodney Laurent: - The default instance is empty 2026-07-31: Validated with Rodney Laurent: No business databases found. | U9: 2026-07-30: validate with Rodney: - Validate if exists any additional instance different than the default (2026-07-31: validated with Rodney, It has no additional instances) | V9: Access is available, but the technical review is incomplete; instance-level features and performance evidence remain pending. | W9: Complete the instance inventory and validate features, jobs, performance, HA/DR, backups, security, and connectivity.
A10: SRV-009 | B10: BBFBDBVIEW | C10: 10.196.5.31 | D10: Orlando | E10: Server | F10: Microsoft SQL Server 2019 (64-bit) | G10: Standard | H10: =IF(AND(ISNUMBER(SEARCH("Microsoft SQL Server",F10)),ISERROR(SEARCH("LocalDB",F10)),ISERROR(SEARCH("do not have any SQL/database installed",T10)),ISERROR(SEARCH("no business databases found",T10))),"Yes","No") -> Yes | I10: DR | J10: Supported | K10: High | L10: DR | M10: IT Operations Team, Renan Silva | N10: Devs | O10: Infrastructure Team / Documentation | P10: Available - Scope Not Confirmed | Q10: Not Started | R10: =COUNTIF('3. Databases'!$B$2:$B$56,$A10) -> 2 | S10: =COUNTIFS('3. Databases'!$B$2:$B$56,$A10,'3. Databases'!$V$2:$V$56,"<>TBD",'3. Databases'!$V$2:$V$56,"<>") -> 0 | T10: 2026-07-30: - 2 databases (AppVolManager, HorizonEvents) | U10: 2026-07-30: validate with Rodney: - Validate if exists any additional instance different than the default (2026-07-31: validated with Rodney, It has no additional instances) - Who is the Technical Owner so I can contact them? 2026-07-31: contact Renan Silva | V10: Access is available, but the technical review is incomplete; instance-level features and performance evidence remain pending. | W10: Complete the instance inventory and validate features, jobs, performance, HA/DR, backups, security, and connectivity.
A11: SRV-010 | B11: BBFBINTRANET | C11: 10.198.5.141 10.198.5.140 | D11: NAP | E11: Server | F11: MySQL Server 8.0 | G11: - | H11: =IF(AND(ISNUMBER(SEARCH("Microsoft SQL Server",F11)),ISERROR(SEARCH("LocalDB",F11)),ISERROR(SEARCH("do not have any SQL/database installed",T11)),ISERROR(SEARCH("no business databases found",T11))),"Yes","No") -> No | I11: Production | J11: Supported | K11: Medium | L11: DR | M11: IT Operations Team, Renan Silva | O11: Infrastructure Team / Documentation | P11: No Access | Q11: Not Started | R11: =COUNTIF('3. Databases'!$B$2:$B$56,$A11) -> 0 | S11: =COUNTIFS('3. Databases'!$B$2:$B$56,$A11,'3. Databases'!$V$2:$V$56,"<>TBD",'3. Databases'!$V$2:$V$56,"<>") -> 0 | T11: 2026-07-29: Validated with Rodney Laurent: - Non-MSSQL product detected | U11: NA | V11: No SQL Server assessment required unless the scope changes. | W11: No follow-up required for the SQL Server migration assessment.
A12: SRV-011 | B12: BB-FW-AP-001 | C12: 10.20.100.25 | D12: Coral Gables | E12: Server | F12: Microsoft SQL Server Compact 4.0 x64 ENU | G12: - | H12: =IF(AND(ISNUMBER(SEARCH("Microsoft SQL Server",F12)),ISERROR(SEARCH("LocalDB",F12)),ISERROR(SEARCH("do not have any SQL/database installed",T12)),ISERROR(SEARCH("no business databases found",T12))),"Yes","No") -> No | I12: Production | K12: Medium | L12: DR | M12: IT Operations Team | O12: Infrastructure Team / Documentation | P12: No Access | Q12: Not Started | R12: =COUNTIF('3. Databases'!$B$2:$B$56,$A12) -> 0 | S12: =COUNTIFS('3. Databases'!$B$2:$B$56,$A12,'3. Databases'!$V$2:$V$56,"<>TBD",'3. Databases'!$V$2:$V$56,"<>") -> 0 | T12: 2026-07-29: Validated with Rodney Laurent: - No business databases found | U12: SQL Compact | V12: Instance configuration, databases, jobs, feature usage, performance, backup, and HA/DR could not be validated directly. | W12: Request controlled read-only access or a validated technical extract from Infrastructure or the vendor.
A13: SRV-012 | B13: bb-vl-ap-051 | C13: 10.198.5.26 | D13: NAP | E13: Server | F13: Mariadb-server | G13: - | H13: =IF(AND(ISNUMBER(SEARCH("Microsoft SQL Server",F13)),ISERROR(SEARCH("LocalDB",F13)),ISERROR(SEARCH("do not have any SQL/database installed",T13)),ISERROR(SEARCH("no business databases found",T13))),"Yes","No") -> No | I13: Production | L13: DR | M13: IT Operations Team | O13: Infrastructure Team / Documentation | P13: No Access | Q13: Not Started | R13: =COUNTIF('3. Databases'!$B$2:$B$56,$A13) -> 0 | S13: =COUNTIFS('3. Databases'!$B$2:$B$56,$A13,'3. Databases'!$V$2:$V$56,"<>TBD",'3. Databases'!$V$2:$V$56,"<>") -> 0 | T13: 2026-07-29: Validated with Rodney Laurent: - Non-MSSQL product detected | U13: Mariadb | V13: No SQL Server assessment required unless the scope changes. | W13: No follow-up required for the SQL Server migration assessment.
A14: SRV-013 | B14: BB-VV-AP-004 | C14: 10.198.5.127 | D14: NAP | E14: Server | F14: Microsoft SQL Server 2019 (64-bit) | G14: Standard | H14: =IF(AND(ISNUMBER(SEARCH("Microsoft SQL Server",F14)),ISERROR(SEARCH("LocalDB",F14)),ISERROR(SEARCH("do not have any SQL/database installed",T14)),ISERROR(SEARCH("no business databases found",T14))),"Yes","No") -> No | I14: Production | L14: DR | M14: IT Operations Team | O14: Infrastructure Team / Documentation | P14: No Access | Q14: Not Started | R14: =COUNTIF('3. Databases'!$B$2:$B$56,$A14) -> 0 | S14: =COUNTIFS('3. Databases'!$B$2:$B$56,$A14,'3. Databases'!$V$2:$V$56,"<>TBD",'3. Databases'!$V$2:$V$56,"<>") -> 0 | T14: 2026-07-30: Validated with Rodney Laurent: - The default instance is empty 2026-07-31: Validated with Rodney Laurent: - No business databases found | U14: 2026-07-30: validate with Rodney: - Validate if exists any additional instance different than the default (2026-07-31: validated with Rodney, It has no additional instances) | V14: Instance configuration, databases, jobs, feature usage, performance, backup, and HA/DR could not be validated directly. | W14: Request controlled read-only access or a validated technical extract from Infrastructure or the vendor.
A15: SRV-014 | B15: BB-VV-AP-009 | C15: 10.198.5.149 | D15: NAP | E15: Server | F15: Microsoft SQL Server 2019 (64-bit) | G15: Standard | H15: =IF(AND(ISNUMBER(SEARCH("Microsoft SQL Server",F15)),ISERROR(SEARCH("LocalDB",F15)),ISERROR(SEARCH("do not have any SQL/database installed",T15)),ISERROR(SEARCH("no business databases found",T15))),"Yes","No") -> Yes | I15: Production | J15: Supported | K15: Medium | L15: DR | M15: IT Operations Team | N15: Finance | O15: Infrastructure Team / Documentation | P15: Available - Scope Not Confirmed | Q15: Not Started | R15: =COUNTIF('3. Databases'!$B$2:$B$56,$A15) -> 0 | S15: =COUNTIFS('3. Databases'!$B$2:$B$56,$A15,'3. Databases'!$V$2:$V$56,"<>TBD",'3. Databases'!$V$2:$V$56,"<>") -> 0 | T15: 2026-07-30: - 1 database (BB_PROLOGUE) | U15: 2026-07-30: validate with Rodney: - Validate if exists any additional instance different than the default (2026-07-31: validated with Rodney, It has no additional instances) - Who is the Technical Owner so I can contact them? 2026-07-31: contact Caddiel Campos/Paul Ippolito - Vendor: Prologue | V15: Access is available, but the technical review is incomplete; instance-level features and performance evidence remain pending. | W15: Complete the instance inventory and validate features, jobs, performance, HA/DR, backups, security, and connectivity.
A16: SRV-015 | B16: BB-VV-BD-001 | C16: 10.198.5.71 | D16: NAP | E16: Server | F16: Microsoft SQL Server 2019 (64-bit) | G16: Standard | H16: =IF(AND(ISNUMBER(SEARCH("Microsoft SQL Server",F16)),ISERROR(SEARCH("LocalDB",F16)),ISERROR(SEARCH("do not have any SQL/database installed",T16)),ISERROR(SEARCH("no business databases found",T16))),"Yes","No") -> Yes | I16: Production | J16: Supported | K16: High | L16: DR | M16: IT Operations Team, Eric | N16: DataWarehouse | O16: Infrastructure Team / Documentation | P16: Available - Scope Not Confirmed | Q16: In Progress | R16: =COUNTIF('3. Databases'!$B$2:$B$56,$A16) -> 0 | S16: =COUNTIFS('3. Databases'!$B$2:$B$56,$A16,'3. Databases'!$V$2:$V$56,"<>TBD",'3. Databases'!$V$2:$V$56,"<>") -> 0 | T16: MSSQL detected | U16: 2026-07-30: validate with Rodney: - Validate if exists any additional instance different than the default (2026-07-31: validated with Rodney, It has no additional instances) - Who is the Technical Owner so I can contact them? 2026-07-31: contact Eric (in decomission), sera reemplazada por la BB-VV-BD-001 | V16: Access is available, but the technical review is incomplete; instance-level features and performance evidence remain pending. | W16: Complete the instance inventory and validate features, jobs, performance, HA/DR, backups, security, and connectivity.
A17: SRV-042 | B17: BB-VV-BD-001 | C17: 10.198.5.71 | D17: NAP | E17: Server | F17: Microsoft SQL Server 2016 LocalDB | G17: Standard | H17: =IF(AND(ISNUMBER(SEARCH("Microsoft SQL Server",F17)),ISERROR(SEARCH("LocalDB",F17)),ISERROR(SEARCH("do not have any SQL/database installed",T17)),ISERROR(SEARCH("no business databases found",T17))),"Yes","No") -> No | I17: Production | K17: Medium | L17: DR | M17: IT Operations Team | N17: DataWarehouse | O17: Infrastructure Team / Documentation | P17: No Access | Q17: Not Started | R17: =COUNTIF('3. Databases'!$B$2:$B$56,$A17) -> 0 | S17: =COUNTIFS('3. Databases'!$B$2:$B$56,$A17,'3. Databases'!$V$2:$V$56,"<>TBD",'3. Databases'!$V$2:$V$56,"<>") -> 0 | T17: MSSQL detected | U17: NA | V17: Instance configuration, databases, jobs, feature usage, performance, backup, and HA/DR could not be validated directly. | W17: Request controlled read-only access or a validated technical extract from Infrastructure or the vendor.
A18: SRV-017 | B18: BB-VV-BD-004 | C18: 10.198.5.144 | D18: NAP | E18: Server | F18: Microsoft SQL Server 2019 (64-bit) | G18: Standard | H18: =IF(AND(ISNUMBER(SEARCH("Microsoft SQL Server",F18)),ISERROR(SEARCH("LocalDB",F18)),ISERROR(SEARCH("do not have any SQL/database installed",T18)),ISERROR(SEARCH("no business databases found",T18))),"Yes","No") -> Yes | I18: Production | J18: Supported | K18: High | L18: DR | M18: IT Operations Team | N18: Operations Deparment | O18: Infrastructure Team / Documentation | P18: Available - Scope Not Confirmed | Q18: Not Started | R18: =COUNTIF('3. Databases'!$B$2:$B$56,$A18) -> 0 | S18: =COUNTIFS('3. Databases'!$B$2:$B$56,$A18,'3. Databases'!$V$2:$V$56,"<>TBD",'3. Databases'!$V$2:$V$56,"<>") -> 0 | T18: 2026-07-30: - 10 databases | U18: 2026-07-30: validate with Rodney: - Validate if exists any additional instance different than the default (2026-07-31: validated with Rodney, It has no additional instances) - Who is the Technical Owner so I can contact them? 2026-07-31: Vendor: Synergy, (JHA) Jack Henry Product, Technical Owner: Rodney Laurent, Caddiel and Infra | V18: Access is available, but the technical review is incomplete; instance-level features and performance evidence remain pending. | W18: Complete the instance inventory and validate features, jobs, performance, HA/DR, backups, security, and connectivity.
A19: SRV-054 | B19: BB-VV-BD-005 | E19: Server | F19: Microsoft SQL Server 2019 (64-bit) | G19: Standard | H19: =IF(AND(ISNUMBER(SEARCH("Microsoft SQL Server",F19)),ISERROR(SEARCH("LocalDB",F19)),ISERROR(SEARCH("do not have any SQL/database installed",T19)),ISERROR(SEARCH("no business databases found",T19))),"Yes","No") -> Yes | I19: Production | J19: Supported | K19: Medium | L19: DR | M19: IT Operations Team, Renan Silva | N19: DataWarehouse | O19: Linked Server Analysis | P19: No Access | Q19: Not Started | R19: =COUNTIF('3. Databases'!$B$2:$B$56,$A19) -> 1 | S19: =COUNTIFS('3. Databases'!$B$2:$B$56,$A19,'3. Databases'!$V$2:$V$56,"<>TBD",'3. Databases'!$V$2:$V$56,"<>") -> 0 | T19: 2026-07-30: - 1 database (DigitalBanking_PROD) | U19: 2026-07-30: Consulté a Rodney si podemos tener acceso 2026-07-30: validate with Rodney: - Validate if exists any additional instance different than the default (2026-07-31: Rodney has not access to validate if exists additional instances) - Who is the Technical Owner so I can contact them? 2026-07-31: contact Renan Silva | V19: Instance configuration, databases, jobs, feature usage, performance, backup, and HA/DR could not be validated directly. | W19: Request controlled read-only access or a validated technical extract from Infrastructure or the vendor.
A20: SRV-053 | B20: BB-VV-BD-006 | C20: 10.198.5.148 | D20: NAP | E20: Server | F20: Microsoft SQL Server 2022 (64-bit) | G20: Unknown | H20: =IF(AND(ISNUMBER(SEARCH("Microsoft SQL Server",F20)),ISERROR(SEARCH("LocalDB",F20)),ISERROR(SEARCH("do not have any SQL/database installed",T20)),ISERROR(SEARCH("no business databases found",T20))),"Yes","No") -> Yes | I20: Production | J20: Supported | K20: Medium | L20: DR | M20: IT Operations Team, Renan Silva | N20: DataWarehouse | O20: Other Team | P20: Available - Scope Not Confirmed | Q20: Not Started | R20: =COUNTIF('3. Databases'!$B$2:$B$56,$A20) -> 0 | S20: =COUNTIFS('3. Databases'!$B$2:$B$56,$A20,'3. Databases'!$V$2:$V$56,"<>TBD",'3. Databases'!$V$2:$V$56,"<>") -> 0 | T20: MSSQL detected | U20: 2026-07-30: validate with Rodney: - Validate if exists any additional instance different than the default (2026-07-31: Rodney has not access to validate if exists additional instances) - Who is the Technical Owner so I can contact them? 2026-07-31: contact Renan Silva | V20: Access is available, but the technical review is incomplete; instance-level features and performance evidence remain pending. | W20: Complete the instance inventory and validate features, jobs, performance, HA/DR, backups, security, and connectivity.
A21: SRV-056 | B21: BB-VV-BD-008 | E21: Server | F21: Microsoft SQL Server 2022 (64-bit) | G21: Unknown | H21: =IF(AND(ISNUMBER(SEARCH("Microsoft SQL Server",F21)),ISERROR(SEARCH("LocalDB",F21)),ISERROR(SEARCH("do not have any SQL/database installed",T21)),ISERROR(SEARCH("no business databases found",T21))),"Yes","No") -> Yes | I21: Development | M21: Renan Silva | N21: Devs | O21: Linked Server Analysis | P21: No Access | Q21: Not Started | R21: =COUNTIF('3. Databases'!$B$2:$B$56,$A21) -> 0 | S21: =COUNTIFS('3. Databases'!$B$2:$B$56,$A21,'3. Databases'!$V$2:$V$56,"<>TBD",'3. Databases'!$V$2:$V$56,"<>") -> 0 | T21: 2027-07-28: Rodney flag this server as red (No SQL Database Installed), but we have detected 5 databases there | U21: 2026-07-30: validate with Rodney: - Validate if exists any additional instance different than the default (2026-07-31: Rodney has not permission to connect) 2026-07-31: contact Renan Silva | V21: Instance configuration, databases, jobs, feature usage, performance, backup, and HA/DR could not be validated directly. | W21: Request controlled read-only access or a validated technical extract from Infrastructure or the vendor.
A22: SRV-018 | B22: BB-VV-DC-001 | C22: 10.198.5.69 10.198.5.134 10.198.5.192 | D22: NAP | E22: Server | F22: Microsoft SQL Server Compact 4.0 SP1 x64 ENU | G22: - | H22: =IF(AND(ISNUMBER(SEARCH("Microsoft SQL Server",F22)),ISERROR(SEARCH("LocalDB",F22)),ISERROR(SEARCH("do not have any SQL/database installed",T22)),ISERROR(SEARCH("no business databases found",T22))),"Yes","No") -> No | I22: Production | K22: High | L22: DR | M22: IT Operations Team | N22: Infrastructure Team | O22: Infrastructure Team / Documentation | P22: No Access | Q22: Not Started | R22: =COUNTIF('3. Databases'!$B$2:$B$56,$A22) -> 0 | S22: =COUNTIFS('3. Databases'!$B$2:$B$56,$A22,'3. Databases'!$V$2:$V$56,"<>TBD",'3. Databases'!$V$2:$V$56,"<>") -> 0 | T22: 2026-07-29: Validated with Rodney Laurent: No business databases found. Flag it as Out of Scope | U22: SQL Compact | V22: Instance configuration, databases, jobs, feature usage, performance, backup, and HA/DR could not be validated directly. | W22: Request controlled read-only access or a validated technical extract from Infrastructure or the vendor.
A23: SRV-016 | B23: BB-VV-HV-001 | C23: 10.198.5.179 | D23: NAP | E23: Server | F23: Microsoft SQL Server 2016 (64-bit) | G23: Standard | H23: =IF(AND(ISNUMBER(SEARCH("Microsoft SQL Server",F23)),ISERROR(SEARCH("LocalDB",F23)),ISERROR(SEARCH("do not have any SQL/database installed",T23)),ISERROR(SEARCH("no business databases found",T23))),"Yes","No") -> Yes | I23: Production | L23: DR | M23: IT Operations Team, Renan Silva | O23: Infrastructure Team / Documentation | P23: No Access | Q23: Not Started | R23: =COUNTIF('3. Databases'!$B$2:$B$56,$A23) -> 0 | S23: =COUNTIFS('3. Databases'!$B$2:$B$56,$A23,'3. Databases'!$V$2:$V$56,"<>TBD",'3. Databases'!$V$2:$V$56,"<>") -> 0 | T23: 2026-07-28: Rodney Laurent: No SQL Database Installed | U23: 2026-07-30: validate with Rodney: - Rodney got an error: The database svmanager_production is not accessible (instance SQLEXPRESS) - Rodney's recommendation: Ask Renan about server - Using SSMS from outside the server - Validate if exists any additional instance different than the default (2026-07-31: Rodney has not access to validate if exists additional instances) 2026-07-31: contact Renan Silva | V23: Instance configuration, databases, jobs, feature usage, performance, backup, and HA/DR could not be validated directly. | W23: Request controlled read-only access or a validated technical extract from Infrastructure or the vendor.
A24: SRV-020 | B24: BB-VV-HV-001 | C24: 10.198.5.179 | D24: NAP | E24: Server | F24: Microsoft SQL Server 2019 (64-bit) | G24: Standard | H24: =IF(AND(ISNUMBER(SEARCH("Microsoft SQL Server",F24)),ISERROR(SEARCH("LocalDB",F24)),ISERROR(SEARCH("do not have any SQL/database installed",T24)),ISERROR(SEARCH("no business databases found",T24))),"Yes","No") -> No | I24: Production | J24: Supported | K24: High | L24: DR | M24: IT Operations Team, Renan Silva | O24: Infrastructure Team / Documentation | P24: No Access | Q24: Not Started | R24: =COUNTIF('3. Databases'!$B$2:$B$56,$A24) -> 0 | S24: =COUNTIFS('3. Databases'!$B$2:$B$56,$A24,'3. Databases'!$V$2:$V$56,"<>TBD",'3. Databases'!$V$2:$V$56,"<>") -> 0 | T24: 2026-07-28: Rodney Laurent: No SQL Database Installed 2026-07-31: Validated with Rodney Laurent: - No business databases found | U24: 2026-07-30: validate with Rodney: - Rodney got an error: The database svmanager_production is not accessible (instance SQLEXPRESS) - Rodney's recommendation: Ask Renan about server - Using SSMS from outside the server - Validate if exists any additional instance different than the default (2026-07-31: Rodney has not access to validate if exists additional instances) 2026-07-31: contact Renan Silva | V24: Instance configuration, databases, jobs, feature usage, performance, backup, and HA/DR could not be validated directly. | W24: Request controlled read-only access or a validated technical extract from Infrastructure or the vendor.
A25: SRV-021 | B25: BB-VV-SG-002 | C25: 10.196.5.12 | D25: Orlando | E25: Server | F25: Microsoft SQL Server Compact 4.0 SP1 x64 ENU | G25: Express | H25: =IF(AND(ISNUMBER(SEARCH("Microsoft SQL Server",F25)),ISERROR(SEARCH("LocalDB",F25)),ISERROR(SEARCH("do not have any SQL/database installed",T25)),ISERROR(SEARCH("no business databases found",T25))),"Yes","No") -> No | I25: DR | K25: Medium | L25: DR | M25: IT Operations Team | N25: Corporate Security | O25: Infrastructure Team / Documentation | P25: No Access | Q25: Not Started | R25: =COUNTIF('3. Databases'!$B$2:$B$56,$A25) -> 0 | S25: =COUNTIFS('3. Databases'!$B$2:$B$56,$A25,'3. Databases'!$V$2:$V$56,"<>TBD",'3. Databases'!$V$2:$V$56,"<>") -> 0 | T25: 2026-07-29: Validated with Rodney Laurent: No business databases found. Flag it as Out of Scope | U25: SQL Compact | V25: Instance configuration, databases, jobs, feature usage, performance, backup, and HA/DR could not be validated directly. | W25: Request controlled read-only access or a validated technical extract from Infrastructure or the vendor.
A26: SRV-022 | B26: BB-VV-SG-002 | C26: 10.196.5.12 | D26: Orlando | E26: Server | F26: Microsoft SQL Server 2019 (64-bit) | G26: Standard | H26: =IF(AND(ISNUMBER(SEARCH("Microsoft SQL Server",F26)),ISERROR(SEARCH("LocalDB",F26)),ISERROR(SEARCH("do not have any SQL/database installed",T26)),ISERROR(SEARCH("no business databases found",T26))),"Yes","No") -> No | I26: DR | O26: Infrastructure Team / Documentation | P26: No Access | Q26: Not Started | R26: =COUNTIF('3. Databases'!$B$2:$B$56,$A26) -> 0 | S26: =COUNTIFS('3. Databases'!$B$2:$B$56,$A26,'3. Databases'!$V$2:$V$56,"<>TBD",'3. Databases'!$V$2:$V$56,"<>") -> 0 | T26: 2026-07-29: Validated with Rodney Laurent: - SSMS not installed 2026-07-31: Validated with Rodney Laurent: do not have any SQL/database installed | U26: 2026-07-30: validate with Rodney: - Using SSMS from outside the server - Validate if exists any additional instance different than the default 2026-07-31: validated with Rodney, there is no connection with SQL Server | V26: Instance configuration, databases, jobs, feature usage, performance, backup, and HA/DR could not be validated directly. | W26: Request controlled read-only access or a validated technical extract from Infrastructure or the vendor.
A27: SRV-023 | B27: BB-VV-WS-002 | C27: 172.29.5.42 | D27: NAP | E27: DMZ | F27: MySQL Server 8.4 | G27: - | H27: =IF(AND(ISNUMBER(SEARCH("Microsoft SQL Server",F27)),ISERROR(SEARCH("LocalDB",F27)),ISERROR(SEARCH("do not have any SQL/database installed",T27)),ISERROR(SEARCH("no business databases found",T27))),"Yes","No") -> No | I27: Production | K27: High | L27: DR | M27: IT Operations Team, Renan Silva | N27: To confirm | O27: Infrastructure Team / Documentation | P27: No Access | Q27: Not Started | R27: =COUNTIF('3. Databases'!$B$2:$B$56,$A27) -> 0 | S27: =COUNTIFS('3. Databases'!$B$2:$B$56,$A27,'3. Databases'!$V$2:$V$56,"<>TBD",'3. Databases'!$V$2:$V$56,"<>") -> 0 | T27: Non-MSSQL product detected | U27: NA | V27: No SQL Server assessment required unless the scope changes. | W27: No follow-up required for the SQL Server migration assessment.
A28: SRV-019 | B28: BFBASSIST | C28: 10.198.5.104 | D28: NAP | E28: Server | F28: Microsoft SQL Server 2016 (64-bit) | G28: Standard | H28: =IF(AND(ISNUMBER(SEARCH("Microsoft SQL Server",F28)),ISERROR(SEARCH("LocalDB",F28)),ISERROR(SEARCH("do not have any SQL/database installed",T28)),ISERROR(SEARCH("no business databases found",T28))),"Yes","No") -> Yes | I28: Production | J28: End of Support (EOS) | K28: High | L28: DR | M28: IT Operations Team, Yanniel | N28: BSA | O28: Infrastructure Team / Documentation | P28: Available - Scope Not Confirmed | Q28: Not Started | R28: =COUNTIF('3. Databases'!$B$2:$B$56,$A28) -> 1 | S28: =COUNTIFS('3. Databases'!$B$2:$B$56,$A28,'3. Databases'!$V$2:$V$56,"<>TBD",'3. Databases'!$V$2:$V$56,"<>") -> 0 | T28: MSSQL detected | U28: 2026-07-30: validate with Rodney: - Validate if exists any additional instance different than the default (2026-07-31: validated with Rodney, It has no additional instances) | V28: Access is available, but the technical review is incomplete; instance-level features and performance evidence remain pending. | W28: Complete the instance inventory and validate features, jobs, performance, HA/DR, backups, security, and connectivity.
A29: SRV-025 | B29: BFBASSIST | C29: 10.198.5.104 | D29: NAP | E29: Server | F29: Microsoft SQL Server 2012 Express LocalDB | G29: Express | H29: =IF(AND(ISNUMBER(SEARCH("Microsoft SQL Server",F29)),ISERROR(SEARCH("LocalDB",F29)),ISERROR(SEARCH("do not have any SQL/database installed",T29)),ISERROR(SEARCH("no business databases found",T29))),"Yes","No") -> No | I29: Production | J29: End of Support (EOS) | K29: Medium | L29: DR | M29: IT Operations Team, Yanniel | N29: BSA | O29: Infrastructure Team / Documentation | P29: No Access | Q29: Not Started | R29: =COUNTIF('3. Databases'!$B$2:$B$56,$A29) -> 0 | S29: =COUNTIFS('3. Databases'!$B$2:$B$56,$A29,'3. Databases'!$V$2:$V$56,"<>TBD",'3. Databases'!$V$2:$V$56,"<>") -> 0 | T29: Duplicate 2026-07-31: Validated with Rodney Laurent: - No business databases found | U29: NA | V29: Instance configuration, databases, jobs, feature usage, performance, backup, and HA/DR could not be validated directly. | W29: Request controlled read-only access or a validated technical extract from Infrastructure or the vendor.
A30: SRV-024 | B30: BFBASSIST-UAT | C30: 10.198.5.6 | D30: NAP | E30: Server | F30: Microsoft SQL Server 2016 (64-bit) | G30: Standard | H30: =IF(AND(ISNUMBER(SEARCH("Microsoft SQL Server",F30)),ISERROR(SEARCH("LocalDB",F30)),ISERROR(SEARCH("do not have any SQL/database installed",T30)),ISERROR(SEARCH("no business databases found",T30))),"Yes","No") -> Yes | I30: Staging/UAT | K30: Medium | L30: DR | M30: IT Operations Team, Yanniel | N30: BSA | O30: Infrastructure Team / Documentation | P30: Available - Scope Not Confirmed | Q30: Not Started | R30: =COUNTIF('3. Databases'!$B$2:$B$56,$A30) -> 2 | S30: =COUNTIFS('3. Databases'!$B$2:$B$56,$A30,'3. Databases'!$V$2:$V$56,"<>TBD",'3. Databases'!$V$2:$V$56,"<>") -> 0 | T30: MSSQL detected | U30: 2026-07-30: validate with Rodney: - Validate if exists any additional instance different than the default (2026-07-31: validated with Rodney, It has no additional instances) | V30: Access is available, but the technical review is incomplete; instance-level features and performance evidence remain pending. | W30: Complete the instance inventory and validate features, jobs, performance, HA/DR, backups, security, and connectivity.
A31: SRV-028 | B31: BFBASSIST-UAT | C31: 10.198.5.6 | D31: NAP | E31: Server | F31: Microsoft SQL Server 2012 Express LocalDB | G31: Express | H31: =IF(AND(ISNUMBER(SEARCH("Microsoft SQL Server",F31)),ISERROR(SEARCH("LocalDB",F31)),ISERROR(SEARCH("do not have any SQL/database installed",T31)),ISERROR(SEARCH("no business databases found",T31))),"Yes","No") -> No | I31: Staging/UAT | M31: IT Operations Team, Yanniel | O31: Infrastructure Team / Documentation | P31: No Access | Q31: Not Started | R31: =COUNTIF('3. Databases'!$B$2:$B$56,$A31) -> 0 | S31: =COUNTIFS('3. Databases'!$B$2:$B$56,$A31,'3. Databases'!$V$2:$V$56,"<>TBD",'3. Databases'!$V$2:$V$56,"<>") -> 0 | T31: Duplicate | U31: NA | V31: Instance configuration, databases, jobs, feature usage, performance, backup, and HA/DR could not be validated directly. | W31: Request controlled read-only access or a validated technical extract from Infrastructure or the vendor.
A32: SRV-029 | B32: BFBDSNAP | C32: 192.168.105.10 169.254.149.78 | D32: NAP | E32: PCI | F32: Microsoft SQL Server 2022 (64-bit) | G32: Standard | H32: =IF(AND(ISNUMBER(SEARCH("Microsoft SQL Server",F32)),ISERROR(SEARCH("LocalDB",F32)),ISERROR(SEARCH("do not have any SQL/database installed",T32)),ISERROR(SEARCH("no business databases found",T32))),"Yes","No") -> Yes | I32: Production | J32: Supported | K32: High | L32: DR | M32: IT Operations Team, Renan Silva | N32: Devs | O32: Infrastructure Team / Documentation | P32: Available - Scope Not Confirmed | Q32: Not Started | R32: =COUNTIF('3. Databases'!$B$2:$B$56,$A32) -> 7 | S32: =COUNTIFS('3. Databases'!$B$2:$B$56,$A32,'3. Databases'!$V$2:$V$56,"<>TBD",'3. Databases'!$V$2:$V$56,"<>") -> 0 | T32: 2026-07-28: Rodney Laurent informed: No SQL Database Installed | U32: 2026-07-30: validate with Rodney: - Using SSMS from outside the server - Validate if exists any additional instance different than the default 2026-07-31: validated with Rodney: corporate security 2026-07-30: contact Renan Silva, Fabiano | V32: Access is available, but the technical review is incomplete; instance-level features and performance evidence remain pending. | W32: Complete the instance inventory and validate features, jobs, performance, HA/DR, backups, security, and connectivity.
A33: SRV-044 | B33: BFBDSNAP | C33: 192.168.105.10 169.254.149.78 | D33: NAP | E33: PCI | F33: Microsoft SQL Server 2016 LocalDB | G33: Standard | H33: =IF(AND(ISNUMBER(SEARCH("Microsoft SQL Server",F33)),ISERROR(SEARCH("LocalDB",F33)),ISERROR(SEARCH("do not have any SQL/database installed",T33)),ISERROR(SEARCH("no business databases found",T33))),"Yes","No") -> No | I33: Production | M33: IT Operations Team, Renan Silva | O33: Infrastructure Team / Documentation | P33: No Access | Q33: Not Started | R33: =COUNTIF('3. Databases'!$B$2:$B$56,$A33) -> 0 | S33: =COUNTIFS('3. Databases'!$B$2:$B$56,$A33,'3. Databases'!$V$2:$V$56,"<>TBD",'3. Databases'!$V$2:$V$56,"<>") -> 0 | T33: Duplicate | U33: NA | V33: Instance configuration, databases, jobs, feature usage, performance, backup, and HA/DR could not be validated directly. | W33: Request controlled read-only access or a validated technical extract from Infrastructure or the vendor.
A34: SRV-031 | B34: BFBFEDLINK | C34: 10.198.5.128 | D34: NAP | E34: Server | F34: Microsoft SQL Server 2019 (64-bit) | G34: Standard | H34: =IF(AND(ISNUMBER(SEARCH("Microsoft SQL Server",F34)),ISERROR(SEARCH("LocalDB",F34)),ISERROR(SEARCH("do not have any SQL/database installed",T34)),ISERROR(SEARCH("no business databases found",T34))),"Yes","No") -> Yes | I34: Production | J34: Supported | K34: High | L34: DR | M34: IT Operations Team, Vendor | N34: Operations Deparment | O34: Infrastructure Team / Documentation | P34: No Access | Q34: Not Started | R34: =COUNTIF('3. Databases'!$B$2:$B$56,$A34) -> 0 | S34: =COUNTIFS('3. Databases'!$B$2:$B$56,$A34,'3. Databases'!$V$2:$V$56,"<>TBD",'3. Databases'!$V$2:$V$56,"<>") -> 0 | T34: 2026-07-28: - Rodney Laurent: servers managed by the vendor | U34: 2026-07-30: validate with Rodney: - Managed by the vendor | V34: Instance configuration, databases, jobs, feature usage, performance, backup, and HA/DR could not be validated directly. | W34: Request controlled read-only access or a validated technical extract from Infrastructure or the vendor.
A35: SRV-055 | B35: BFB-FEDLINK | E35: Server | F35: Microsoft SQL Server 2019 (64-bit) | G35: Standard | H35: =IF(AND(ISNUMBER(SEARCH("Microsoft SQL Server",F35)),ISERROR(SEARCH("LocalDB",F35)),ISERROR(SEARCH("do not have any SQL/database installed",T35)),ISERROR(SEARCH("no business databases found",T35))),"Yes","No") -> Yes | I35: Production | J35: Supported | K35: High | L35: DR | M35: IT Operations Team, Vendor | N35: Operations Deparment | O35: Linked Server Analysis | P35: No Access | Q35: Not Started | R35: =COUNTIF('3. Databases'!$B$2:$B$56,$A35) -> 0 | S35: =COUNTIFS('3. Databases'!$B$2:$B$56,$A35,'3. Databases'!$V$2:$V$56,"<>TBD",'3. Databases'!$V$2:$V$56,"<>") -> 0 | T35: 2026-07-28: - Rodney Laurent: servers managed by the vendor | U35: 2026-07-30: validate with Rodney: - Managed by the vendor | V35: Instance configuration, databases, jobs, feature usage, performance, backup, and HA/DR could not be validated directly. | W35: Request controlled read-only access or a validated technical extract from Infrastructure or the vendor.
A36: SRV-032 | B36: BFBFEDLINKORL | C36: 10.196.5.24 | D36: Orlando | E36: Server | F36: Microsoft SQL Server 2019 (64-bit) | G36: Standard | H36: =IF(AND(ISNUMBER(SEARCH("Microsoft SQL Server",F36)),ISERROR(SEARCH("LocalDB",F36)),ISERROR(SEARCH("do not have any SQL/database installed",T36)),ISERROR(SEARCH("no business databases found",T36))),"Yes","No") -> Yes | I36: DR | J36: Supported | K36: High | L36: DR | M36: IT Operations Team, Vendor | N36: Operations Deparment | O36: Infrastructure Team / Documentation | P36: No Access | Q36: Not Started | R36: =COUNTIF('3. Databases'!$B$2:$B$56,$A36) -> 0 | S36: =COUNTIFS('3. Databases'!$B$2:$B$56,$A36,'3. Databases'!$V$2:$V$56,"<>TBD",'3. Databases'!$V$2:$V$56,"<>") -> 0 | T36: 2026-07-28: - Rodney Laurent: servers managed by the vendor | U36: 2026-07-30: validate with Rodney: - Managed by the vendor | V36: Instance configuration, databases, jobs, feature usage, performance, backup, and HA/DR could not be validated directly. | W36: Request controlled read-only access or a validated technical extract from Infrastructure or the vendor.
A37: SRV-033 | B37: BFBJXSERVER1 | C37: 10.198.5.170 10.198.5.221 | D37: NAP | E37: Server | F37: Microsoft SQL Server Compact 3.5 SP2 ENU | G37: - | H37: =IF(AND(ISNUMBER(SEARCH("Microsoft SQL Server",F37)),ISERROR(SEARCH("LocalDB",F37)),ISERROR(SEARCH("do not have any SQL/database installed",T37)),ISERROR(SEARCH("no business databases found",T37))),"Yes","No") -> No | I37: Production | J37: End of Support (EOS) | K37: Medium | L37: DR | M37: IT Operations Team | N37: Operations Deparment | O37: Infrastructure Team / Documentation | P37: No Access | Q37: Not Started | R37: =COUNTIF('3. Databases'!$B$2:$B$56,$A37) -> 0 | S37: =COUNTIFS('3. Databases'!$B$2:$B$56,$A37,'3. Databases'!$V$2:$V$56,"<>TBD",'3. Databases'!$V$2:$V$56,"<>") -> 0 | T37: 2026-07-28: - Rodney Laurent: do not have any SQL/database installed | U37: SQL Compact | V37: Instance configuration, databases, jobs, feature usage, performance, backup, and HA/DR could not be validated directly. | W37: Request controlled read-only access or a validated technical extract from Infrastructure or the vendor.
A38: SRV-034 | B38: BFBJXSERVER2 | C38: 10.198.5.171 10.198.5.222 | D38: NAP | E38: Server | F38: Microsoft SQL Server Compact 3.5 SP2 ENU | G38: - | H38: =IF(AND(ISNUMBER(SEARCH("Microsoft SQL Server",F38)),ISERROR(SEARCH("LocalDB",F38)),ISERROR(SEARCH("do not have any SQL/database installed",T38)),ISERROR(SEARCH("no business databases found",T38))),"Yes","No") -> No | I38: Production | J38: End of Support (EOS) | K38: Medium | L38: DR | M38: IT Operations Team | N38: Operations Deparment | O38: Infrastructure Team / Documentation | P38: No Access | Q38: Not Started | R38: =COUNTIF('3. Databases'!$B$2:$B$56,$A38) -> 0 | S38: =COUNTIFS('3. Databases'!$B$2:$B$56,$A38,'3. Databases'!$V$2:$V$56,"<>TBD",'3. Databases'!$V$2:$V$56,"<>") -> 0 | T38: 2026-07-28: - Rodney Laurent: do not have any SQL/database installed | U38: SQL Compact | V38: Instance configuration, databases, jobs, feature usage, performance, backup, and HA/DR could not be validated directly. | W38: Request controlled read-only access or a validated technical extract from Infrastructure or the vendor.
A39: SRV-035 | B39: BFBJXSERVERDB\JXCHANGE | C39: 10.198.5.108 | D39: NAP | E39: Server | F39: Microsoft SQL Server 2019 (64-bit) | G39: Standard | H39: =IF(AND(ISNUMBER(SEARCH("Microsoft SQL Server",F39)),ISERROR(SEARCH("LocalDB",F39)),ISERROR(SEARCH("do not have any SQL/database installed",T39)),ISERROR(SEARCH("no business databases found",T39))),"Yes","No") -> Yes | I39: Production | J39: Supported | K39: High | L39: DR | M39: IT Operations Team, Caddiel Campos | N39: Operations Deparment | O39: Infrastructure Team / Documentation | P39: Available - Scope Not Confirmed | Q39: Not Started | R39: =COUNTIF('3. Databases'!$B$2:$B$56,$A39) -> 0 | S39: =COUNTIFS('3. Databases'!$B$2:$B$56,$A39,'3. Databases'!$V$2:$V$56,"<>TBD",'3. Databases'!$V$2:$V$56,"<>") -> 0 | T39: MSSQL detected | U39: 2026-07-30: validate with Rodney: - Who is the Technical Owner so I can contact them? 2026-07-31: JX Jack Henry, Vendor: JHA, Caddiel Campos | V39: Access is available, but the technical review is incomplete; instance-level features and performance evidence remain pending. | W39: Complete the instance inventory and validate features, jobs, performance, HA/DR, backups, security, and connectivity.
A40: SRV-036 | B40: BFBJXWORKFLOWDB | C40: 10.198.5.37 | D40: NAP | E40: Server | F40: Microsoft SQL Server 2019 (64-bit) | G40: Standard | H40: =IF(AND(ISNUMBER(SEARCH("Microsoft SQL Server",F40)),ISERROR(SEARCH("LocalDB",F40)),ISERROR(SEARCH("do not have any SQL/database installed",T40)),ISERROR(SEARCH("no business databases found",T40))),"Yes","No") -> Yes | I40: Production | J40: Supported | K40: High | L40: DR | M40: IT Operations Team | N40: Operations Deparment | O40: Infrastructure Team / Documentation | P40: Available - Scope Not Confirmed | Q40: Not Started | R40: =COUNTIF('3. Databases'!$B$2:$B$56,$A40) -> 0 | S40: =COUNTIFS('3. Databases'!$B$2:$B$56,$A40,'3. Databases'!$V$2:$V$56,"<>TBD",'3. Databases'!$V$2:$V$56,"<>") -> 0 | T40: MSSQL detected | U40: 2026-07-30: validate with Rodney: - Who is the Technical Owner so I can contact them? 2026-07-31: JX Jack Henry, Vendor: JHA | V40: Access is available, but the technical review is incomplete; instance-level features and performance evidence remain pending. | W40: Complete the instance inventory and validate features, jobs, performance, HA/DR, backups, security, and connectivity.
...

Sheet 3. Databases
A1: DatabaseID | B1: ServerID (link to Tab 2) | C1: Server | D1: Database Name | E1: SQL Version (reported) | F1: State | G1: Size (MB) | H1: Last Backup | I1: mdf | J1: ldf | K1: Environment | L1: Criticality | M1: Application / Functional Owner | N1: Business Purpose | O1: Usage Status | P1: Source Systems | Q1: Source Owner | R1: Dependent Systems / Consumers | S1: Dependency Owner | T1: Integration / Processing | U1: Assessment Status | V1: Preliminary Disposition | W1: Assessment Confidence | X1: Discovery Source | Y1: Open Questions / Next Action | Z1: Notes | AA1: RTO / RPO Required | AB1: Maximum Downtime / Cutover Window | AC1: Operating Window / Peak Period | AD1: Data Classification / Regulatory Scope | AE1: Retention Requirement | AF1: Performance / Growth Baseline | AG1: Technical Compatibility Constraints | AH1: Preliminary Conclusion
A2: DB-126 | B2: SRV-029 | C2: BFBDSNAP | D2: ALERT_FILE_DB | E2: SQL Server 2019 | F2: ONLINE | G2: 1004.69 | H2: 7/14/2026 3:17 | I2: C:\Program Files\Microsoft SQL Server\MSSQL16.MSSQLSERVER\MSSQL\DATA\ALERT_FILE_DB.mdf | J2: C:\Program Files\Microsoft SQL Server\MSSQL16.MSSQLSERVER\MSSQL\DATA\ALERT_FILE_DB_log.ldf | K2: Pending validation | M2: Renan Silva | N2: Purpose not confirmed. | O2: Unknown | P2: Unknown | Q2: Unknown | R2: Unknown | S2: Unknown | T2: Unknown | U2: Pending Analysis | V2: TBD | W2: Low | X2: Linked Server Analysis | AA2: Not Assessed | AB2: Not Assessed | AC2: Not Assessed | AD2: Not Assessed | AE2: Not Assessed | AF2: Not Assessed | AG2: Not Assessed
A3: DB-127 | B3: SRV-029 | C3: BFBDSNAP | D3: ASSIST_IMP_RPTS | E3: SQL Server 2019 | F3: ONLINE | G3: 77456.31 | H3: 7/14/2026 3:17 | I3: C:\Program Files\Microsoft SQL Server\MSSQL16.MSSQLSERVER\MSSQL\DATA\ASSIST_IMP_RPTS.mdf | J3: C:\Program Files\Microsoft SQL Server\MSSQL16.MSSQLSERVER\MSSQL\DATA\ASSIST_IMP_RPTS_log.ldf | K3: Pending validation | M3: Renan Silva | N3: Purpose not confirmed. | O3: Unknown | P3: Unknown | Q3: Unknown | R3: Unknown | S3: Unknown | T3: Unknown | U3: Pending Analysis | V3: TBD | W3: Low | X3: Linked Server Analysis | AA3: Not Assessed | AB3: Not Assessed | AC3: Not Assessed | AD3: Not Assessed | AE3: Not Assessed | AF3: Not Assessed | AG3: Not Assessed
A4: DB-129 | B4: SRV-029 | C4: BFBDSNAP | D4: MISC | E4: SQL Server 2019 | F4: ONLINE | G4: 176 | H4: 7/14/2026 3:17 | I4: C:\Program Files\Microsoft SQL Server\MSSQL16.MSSQLSERVER\MSSQL\DATA\misc.mdf | J4: C:\Program Files\Microsoft SQL Server\MSSQL16.MSSQLSERVER\MSSQL\DATA\misc_log.ldf | K4: Pending validation | M4: Renan Silva | N4: Purpose not confirmed. | O4: Unknown | P4: Unknown | Q4: Unknown | R4: Unknown | S4: Unknown | T4: Unknown | U4: Pending Analysis | V4: TBD | W4: Low | X4: Linked Server Analysis | AA4: Not Assessed | AB4: Not Assessed | AC4: Not Assessed | AD4: Not Assessed | AE4: Not Assessed | AF4: Not Assessed | AG4: Not Assessed
A5: DB-131 | B5: SRV-052 | C5: UATSYNDB | D5: AS400_STAGE | E5: SQL Server 2019 | F5: ONLINE | G5: 528 | H5: 7/14/2026 3:57 | I5: C:\Program Files\Microsoft SQL Server\MSSQL15.MSSQLSERVER\MSSQL\DATA\AS400_STAGE.mdf | J5: C:\Program Files\Microsoft SQL Server\MSSQL15.MSSQLSERVER\MSSQL\DATA\AS400_STAGE_log.ldf | K5: Pending validation | M5: Renan Silva | N5: Purpose not confirmed. | O5: Unknown | P5: Unknown | Q5: Unknown | R5: Unknown | S5: Unknown | T5: Unknown | U5: Pending Analysis | V5: TBD | W5: Low | X5: Linked Server Analysis | AA5: Not Assessed | AB5: Not Assessed | AC5: Not Assessed | AD5: Not Assessed | AE5: Not Assessed | AF5: Not Assessed | AG5: Not Assessed
A6: DB-139 | B6: SRV-052 | C6: UATSYNDB | D6: BAC_Collections | E6: SQL Server 2019 | F6: ONLINE | G6: 40220.81 | H6: 7/14/2026 3:42 | I6: C:\Program Files\Microsoft SQL Server\MSSQL15.MSSQLSERVER\MSSQL\DATA\BAC_Collections.mdf | J6: C:\Program Files\Microsoft SQL Server\MSSQL15.MSSQLSERVER\MSSQL\DATA\BAC_Collections_1.ldf | K6: Staging/UAT | L6: Pending validation | M6: Renan Silva | N6: Staging / UAT database. | O6: Unknown | P6: Unknown | Q6: Unknown | R6: Unknown | S6: Unknown | T6: Unknown | U6: Pending Analysis | V6: TBD | W6: Low | X6: Linked Server Analysis | AA6: Not Assessed | AB6: Not Assessed | AC6: Not Assessed | AD6: Not Assessed | AE6: Not Assessed | AF6: Not Assessed | AG6: Not Assessed
A7: DB-143 | B7: SRV-052 | C7: UATSYNDB | D7: BB_DATA | E7: SQL Server 2019 | F7: ONLINE | G7: 356816 | H7: 7/14/2026 3:57 | I7: C:\Program Files\Microsoft SQL Server\MSSQL15.MSSQLSERVER\MSSQL\DATA\BB_DATA.mdf | J7: C:\Program Files\Microsoft SQL Server\MSSQL15.MSSQLSERVER\MSSQL\DATA\BB_DATA_log.ldf | K7: Pending validation | M7: Renan Silva | N7: Purpose not confirmed. | O7: Unknown | P7: Unknown | Q7: Unknown | R7: Unknown | S7: Unknown | T7: Unknown | U7: Pending Analysis | V7: TBD | W7: Low | X7: Linked Server Analysis | AA7: Not Assessed | AB7: Not Assessed | AC7: Not Assessed | AD7: Not Assessed | AE7: Not Assessed | AF7: Not Assessed | AG7: Not Assessed
A8: DB-144 | B8: SRV-052 | C8: UATSYNDB | D8: BB_DATA_AUX | E8: SQL Server 2019 | F8: ONLINE | G8: 5968 | H8: 7/14/2026 3:57 | I8: C:\Program Files\Microsoft SQL Server\MSSQL15.MSSQLSERVER\MSSQL\DATA\BB_DATA_AUX.mdf | J8: C:\Program Files\Microsoft SQL Server\MSSQL15.MSSQLSERVER\MSSQL\DATA\BB_DATA_AUX_log.ldf | K8: Pending validation | M8: Renan Silva | N8: Purpose not confirmed. | O8: Unknown | P8: Unknown | Q8: Unknown | R8: Unknown | S8: Unknown | T8: Unknown | U8: Pending Analysis | V8: TBD | W8: Low | X8: Linked Server Analysis | AA8: Not Assessed | AB8: Not Assessed | AC8: Not Assessed | AD8: Not Assessed | AE8: Not Assessed | AF8: Not Assessed | AG8: Not Assessed
A9: DB-145 | B9: SRV-052 | C9: UATSYNDB | D9: BB_PROCESS_DATA | E9: SQL Server 2019 | F9: ONLINE | G9: 25296 | H9: 7/14/2026 3:57 | I9: C:\Program Files\Microsoft SQL Server\MSSQL15.MSSQLSERVER\MSSQL\DATA\BB_PROCESS.mdf | J9: C:\Program Files\Microsoft SQL Server\MSSQL15.MSSQLSERVER\MSSQL\DATA\BB_PROCESS_log.ldf | K9: Pending validation | M9: Renan Silva | N9: Purpose not confirmed. | O9: Unknown | P9: Unknown | Q9: Unknown | R9: Unknown | S9: Unknown | T9: Unknown | U9: Pending Analysis | V9: TBD | W9: Low | X9: SQL Server Inspection | AA9: Not Assessed | AB9: Not Assessed | AC9: Not Assessed | AD9: Not Assessed | AE9: Not Assessed | AF9: Not Assessed | AG9: Not Assessed
A10: DB-158 | B10: SRV-052 | C10: UATSYNDB | D10: NICE | E10: SQL Server 2019 | F10: ONLINE | G10: 4560 | H10: 7/14/2026 3:57 | I10: C:\Program Files\Microsoft SQL Server\MSSQL15.MSSQLSERVER\MSSQL\DATA\NICE.mdf | J10: C:\Program Files\Microsoft SQL Server\MSSQL15.MSSQLSERVER\MSSQL\DATA\NICE_log.ldf | K10: Pending validation | M10: Renan Silva | N10: Purpose not confirmed. | O10: Unknown | P10: Unknown | Q10: Unknown | R10: Unknown | S10: Unknown | T10: Unknown | U10: Pending Analysis | V10: TBD | W10: Low | X10: Linked Server Analysis | AA10: Not Assessed | AB10: Not Assessed | AC10: Not Assessed | AD10: Not Assessed | AE10: Not Assessed | AF10: Not Assessed | AG10: Not Assessed
A11: DB-162 | B11: SRV-052 | C11: UATSYNDB | D11: ReportServer_STAGE | E11: SQL Server 2019 | F11: ONLINE | G11: 342.5 | H11: 7/14/2026 3:57 | I11: C:\Program Files\Microsoft SQL Server\MSSQL13.MSSQLSERVER\MSSQL\DATA\ReportServer_STAGE.mdf | J11: C:\Program Files\Microsoft SQL Server\MSSQL13.MSSQLSERVER\MSSQL\DATA\ReportServer_STAGE_1.LDF | K11: Staging/UAT | L11: Low | M11: Renan Silva | N11: Staging / UAT database. | O11: Unknown | P11: Unknown | Q11: Unknown | R11: Unknown | S11: Unknown | T11: Unknown | U11: Pending Analysis | V11: TBD | W11: Low | X11: Linked Server Analysis | AA11: Not Assessed | AB11: Not Assessed | AC11: Not Assessed | AD11: Not Assessed | AE11: Not Assessed | AF11: Not Assessed | AG11: Not Assessed
A12: DB-167 | B12: SRV-052 | C12: UATSYNDB | D12: WFServer | E12: SQL Server 2019 | F12: ONLINE | G12: 528 | H12: 7/14/2026 3:42 | I12: C:\Program Files\Microsoft SQL Server\MSSQL15.MSSQLSERVER\MSSQL\DATA\WFServer_Primary.mdf | J12: C:\Program Files\Microsoft SQL Server\MSSQL15.MSSQLSERVER\MSSQL\DATA\WFServer_Primary.ldf | K12: Pending validation | M12: Renan Silva | N12: Purpose not confirmed. | O12: Unknown | P12: Unknown | Q12: Unknown | R12: Unknown | S12: Unknown | T12: Unknown | U12: Pending Analysis | V12: TBD | W12: Low | X12: Linked Server Analysis | AA12: Not Assessed | AB12: Not Assessed | AC12: Not Assessed | AD12: Not Assessed | AE12: Not Assessed | AF12: Not Assessed | AG12: Not Assessed
A13: DB-168 | B13: SRV-052 | C13: UATSYNDB | D13: WFServerReporting | E13: SQL Server 2019 | F13: ONLINE | G13: 272 | H13: 7/14/2026 3:42 | I13: C:\Program Files\Microsoft SQL Server\MSSQL15.MSSQLSERVER\MSSQL\DATA\WFServerReporting_Primary.mdf | J13: C:\Program Files\Microsoft SQL Server\MSSQL15.MSSQLSERVER\MSSQL\DATA\WFServerReporting_Primary.ldf | K13: Pending validation | M13: Renan Silva | N13: Purpose not confirmed. | O13: Unknown | P13: Unknown | Q13: Unknown | R13: Unknown | S13: Unknown | T13: Unknown | U13: Pending Analysis | V13: TBD | W13: Low | X13: Linked Server Analysis | AA13: Not Assessed | AB13: Not Assessed | AC13: Not Assessed | AD13: Not Assessed | AE13: Not Assessed | AF13: Not Assessed | AG13: Not Assessed
A14: DB-125 | B14: SRV-054 | C14: BB-VV-BD-005 | D14: DigitalBanking_PROD | E14: SQL Server 2019 | F14: ONLINE | G14: 1408 | H14: 7/14/2026 4:04 | I14: D:\MSSQLSERVER\MSSQL\Data\DigitalBanking_PROD.mdf | J14: E:\MSSQLSERVER\MSSQL\Log\DigitalBanking_PROD_log.ldf | K14: Pending validation | M14: Renan Silva | N14: Purpose not confirmed. | O14: Unknown | P14: Unknown | Q14: Unknown | R14: Unknown | S14: Unknown | T14: Unknown | U14: Pending Analysis | V14: TBD | W14: Low | X14: Linked Server Analysis | AA14: Not Assessed | AB14: Not Assessed | AC14: Not Assessed | AD14: Not Assessed | AE14: Not Assessed | AF14: Not Assessed | AG14: Not Assessed
A15: DB-191 | B15: SRV-019 | C15: BFBASSIST | D15: BankTect-VE | E15: SQL Server 2016 | F15: ONLINE | G15: NULL | H15: 46232.168 | I15: NULL | J15: NULL | K15: Pending validation | M15: Renan Silva | N15: Purpose not confirmed. | O15: Unknown | P15: Unknown | Q15: Unknown | R15: Unknown | S15: Unknown | T15: Unknown | U15: Pending Analysis | V15: TBD | W15: Low | X15: Unknown | AA15: Not Assessed | AB15: Not Assessed | AC15: Not Assessed | AD15: Not Assessed | AE15: Not Assessed | AF15: Not Assessed | AG15: Not Assessed
A16: DB-193 | B16: SRV-024 | C16: BFBASSIST-UAT | D16: BankTect | E16: SQL Server 2016 | F16: ONLINE | G16: NULL | H16: 46097.163 | I16: NULL | J16: NULL | K16: Pending validation | M16: Renan Silva | N16: Purpose not confirmed. | O16: Unknown | P16: Unknown | Q16: Unknown | R16: Unknown | S16: Unknown | T16: Unknown | U16: Pending Analysis | V16: TBD | W16: Low | X16: Unknown | AA16: Not Assessed | AB16: Not Assessed | AC16: Not Assessed | AD16: Not Assessed | AE16: Not Assessed | AF16: Not Assessed | AG16: Not Assessed
A17: DB-194 | B17: SRV-024 | C17: BFBASSIST-UAT | D17: BankTect-VE | E17: SQL Server 2016 | F17: ONLINE | G17: NULL | H17: 46097.173 | I17: NULL | J17: NULL | K17: Pending validation | M17: Renan Silva | N17: Purpose not confirmed. | O17: Unknown | P17: Unknown | Q17: Unknown | R17: Unknown | S17: Unknown | T17: Unknown | U17: Pending Analysis | V17: TBD | W17: Low | X17: Unknown | AA17: Not Assessed | AB17: Not Assessed | AC17: Not Assessed | AD17: Not Assessed | AE17: Not Assessed | AF17: Not Assessed | AG17: Not Assessed
A18: DB-195 | B18: SRV-029 | C18: BFBDSNAP | D18: ALERT_FILE_DB | E18: SQL Server 2022 | F18: ONLINE | G18: NULL | H18: 46232.137 | I18: NULL | J18: NULL | K18: Pending validation | M18: Renan Silva | N18: Purpose not confirmed. | O18: Unknown | P18: Unknown | Q18: Unknown | R18: Unknown | S18: Unknown | T18: Unknown | U18: Pending Analysis | V18: TBD | W18: Low | X18: Unknown | AA18: Not Assessed | AB18: Not Assessed | AC18: Not Assessed | AD18: Not Assessed | AE18: Not Assessed | AF18: Not Assessed | AG18: Not Assessed
A19: DB-196 | B19: SRV-029 | C19: BFBDSNAP | D19: ASSIST_IMP_RPTS | E19: SQL Server 2022 | F19: ONLINE | G19: NULL | H19: 46232.137 | I19: NULL | J19: NULL | K19: Pending validation | M19: Renan Silva | N19: Purpose not confirmed. | O19: Unknown | P19: Unknown | Q19: Unknown | R19: Unknown | S19: Unknown | T19: Unknown | U19: Pending Analysis | V19: TBD | W19: Low | X19: Unknown | AA19: Not Assessed | AB19: Not Assessed | AC19: Not Assessed | AD19: Not Assessed | AE19: Not Assessed | AF19: Not Assessed | AG19: Not Assessed
